Workbook

Sheet Parametry
A1: Parametry Modelu Emerytalnego | B1: Wartość
A2: Kapitał Początkowy (PLN) | B2: 1000000
A3: Wydatki Miesięczne dzisiaj (PLN) | B3: 5000
A4: ZUS Miesięczny dzisiaj (PLN) | B4: 2000
A5: Wpłaty Miesięczne przed emeryturą (PLN) | B5: 3000
A6: Inflacja Bazowa Roczna | B6: 0.03
A7: Oczekiwany Zwrot Roczny | B7: 0.05
A8: Wiek Obecny | B8: 53
A9: Wiek Emerytalny | B9: 60
A10: Horyzont (Zakładany Wiek Końcowy) | B10: 65
A11: Podatek od zysków kapitałowych (np. 19% lub 0% IKE) | B11: 0.19
A14: Zmień wartości w zielonych komórkach, aby zaktualizować model.

Sheet Model
A1: Rok symulacji | B1: Wiek | C1: Faza | D1: Mnożnik Inflacji | E1: Kapitał na początku roku | F1: Roczne Wpłaty netto | G1: Roczne ZUS | H1: Wymagane Wydatki Brutto | I1: Wypłata z portfela | J1: Zysk Rynkowy (Brutto) | K1: Baza Kosztowa (do podatku) | L1: Podatek Belki | M1: Kapitał na koniec roku
A2: =IF(Parametry!$B$8+1-1<=Parametry!$B$10, 1, "") -> 1 | B2: =IF(A2="","", Parametry!$B$8+A2-1) -> 53 | C2: =IF(A2="","", IF(B2>=Parametry!$B$9, "Dekumulacja", "Akumulacja")) -> Akumulacja | D2: =IF(A2="","", 1) -> 1 | E2: =IF(A2="","", Parametry!$B$2) -> 1000000 | F2: =IF(A2="","", IF(C2="Akumulacja", Parametry!$B$5*12*D2, 0)) -> 36000 | G2: =IF(A2="","", IF(C2="Dekumulacja", Parametry!$B$4*12*D2, 0)) -> 0 | H2: =IF(A2="","", IF(C2="Dekumulacja", Parametry!$B$3*12*D2, 0)) -> 0 | I2: =IF(A2="","", MAX(0, H2-G2)) -> 0 | J2: =IF(A2="","", MAX(0, E2+F2-I2)*Parametry!$B$7) -> 51800 | K2: =IF(A2="","", MAX(0, Parametry!$B$2 + F2 - I2 * MIN(1, (Parametry!$B$2) / MAX(1, E2+F2)))) -> 1036000 | L2: =IF(A2="","", IF(Parametry!$B$11>0, I2 * (1 - MIN(1, (Parametry!$B$2) / MAX(1, E2+F2))) * Parametry!$B$11, 0)) -> 0 | M2: =IF(A2="","", MAX(0, E2+F2-I2+J2-L2)) -> 1087800
A3: =IF(Parametry!$B$8+2-1<=Parametry!$B$10, 2, "") -> 2 | B3: =IF(A3="","", Parametry!$B$8+A3-1) -> 54 | C3: =IF(A3="","", IF(B3>=Parametry!$B$9, "Dekumulacja", "Akumulacja")) -> Akumulacja | D3: =IF(A3="","", D2*(1+Parametry!$B$6)) -> 1.03 | E3: =IF(A3="","", M2) -> 1087800 | F3: =IF(A3="","", IF(C3="Akumulacja", Parametry!$B$5*12*D3, 0)) -> 37080 | G3: =IF(A3="","", IF(C3="Dekumulacja", Parametry!$B$4*12*D3, 0)) -> 0 | H3: =IF(A3="","", IF(C3="Dekumulacja", Parametry!$B$3*12*D3, 0)) -> 0 | I3: =IF(A3="","", MAX(0, H3-G3)) -> 0 | J3: =IF(A3="","", MAX(0, E3+F3-I3)*Parametry!$B$7) -> 56244 | K3: =IF(A3="","", MAX(0, K2 + F3 - I3 * MIN(1, K2 / MAX(1, E3+F3)))) -> 1073080 | L3: =IF(A3="","", IF(Parametry!$B$11>0, I3 * (1 - MIN(1, K2 / MAX(1, E3+F3))) * Parametry!$B$11, 0)) -> 0 | M3: =IF(A3="","", MAX(0, E3+F3-I3+J3-L3)) -> 1181124
A4: =IF(Parametry!$B$8+3-1<=Parametry!$B$10, 3, "") -> 3 | B4: =IF(A4="","", Parametry!$B$8+A4-1) -> 55 | C4: =IF(A4="","", IF(B4>=Parametry!$B$9, "Dekumulacja", "Akumulacja")) -> Akumulacja | D4: =IF(A4="","", D3*(1+Parametry!$B$6)) -> 1.0609 | E4: =IF(A4="","", M3) -> 1181124 | F4: =IF(A4="","", IF(C4="Akumulacja", Parametry!$B$5*12*D4, 0)) -> 38192.4 | G4: =IF(A4="","", IF(C4="Dekumulacja", Parametry!$B$4*12*D4, 0)) -> 0 | H4: =IF(A4="","", IF(C4="Dekumulacja", Parametry!$B$3*12*D4, 0)) -> 0 | I4: =IF(A4="","", MAX(0, H4-G4)) -> 0 | J4: =IF(A4="","", MAX(0, E4+F4-I4)*Parametry!$B$7) -> 60965.82 | K4: =IF(A4="","", MAX(0, K3 + F4 - I4 * MIN(1, K3 / MAX(1, E4+F4)))) -> 1111272.4 | L4: =IF(A4="","", IF(Parametry!$B$11>0, I4 * (1 - MIN(1, K3 / MAX(1, E4+F4))) * Parametry!$B$11, 0)) -> 0 | M4: =IF(A4="","", MAX(0, E4+F4-I4+J4-L4)) -> 1280282.2
A5: =IF(Parametry!$B$8+4-1<=Parametry!$B$10, 4, "") -> 4 | B5: =IF(A5="","", Parametry!$B$8+A5-1) -> 56 | C5: =IF(A5="","", IF(B5>=Parametry!$B$9, "Dekumulacja", "Akumulacja")) -> Akumulacja | D5: =IF(A5="","", D4*(1+Parametry!$B$6)) -> 1.092727 | E5: =IF(A5="","", M4) -> 1280282.2 | F5: =IF(A5="","", IF(C5="Akumulacja", Parametry!$B$5*12*D5, 0)) -> 39338.172 | G5: =IF(A5="","", IF(C5="Dekumulacja", Parametry!$B$4*12*D5, 0)) -> 0 | H5: =IF(A5="","", IF(C5="Dekumulacja", Parametry!$B$3*12*D5, 0)) -> 0 | I5: =IF(A5="","", MAX(0, H5-G5)) -> 0 | J5: =IF(A5="","", MAX(0, E5+F5-I5)*Parametry!$B$7) -> 65981.02 | K5: =IF(A5="","", MAX(0, K4 + F5 - I5 * MIN(1, K4 / MAX(1, E5+F5)))) -> 1150610.6 | L5: =IF(A5="","", IF(Parametry!$B$11>0, I5 * (1 - MIN(1, K4 / MAX(1, E5+F5))) * Parametry!$B$11, 0)) -> 0 | M5: =IF(A5="","", MAX(0, E5+F5-I5+J5-L5)) -> 1385601.4
A6: =IF(Parametry!$B$8+5-1<=Parametry!$B$10, 5, "") -> 5 | B6: =IF(A6="","", Parametry!$B$8+A6-1) -> 57 | C6: =IF(A6="","", IF(B6>=Parametry!$B$9, "Dekumulacja", "Akumulacja")) -> Akumulacja | D6: =IF(A6="","", D5*(1+Parametry!$B$6)) -> 1.1255088 | E6: =IF(A6="","", M5) -> 1385601.4 | F6: =IF(A6="","", IF(C6="Akumulacja", Parametry!$B$5*12*D6, 0)) -> 40518.317 | G6: =IF(A6="","", IF(C6="Dekumulacja", Parametry!$B$4*12*D6, 0)) -> 0 | H6: =IF(A6="","", IF(C6="Dekumulacja", Parametry!$B$3*12*D6, 0)) -> 0 | I6: =IF(A6="","", MAX(0, H6-G6)) -> 0 | J6: =IF(A6="","", MAX(0, E6+F6-I6)*Parametry!$B$7) -> 71305.986 | K6: =IF(A6="","", MAX(0, K5 + F6 - I6 * MIN(1, K5 / MAX(1, E6+F6)))) -> 1191128.9 | L6: =IF(A6="","", IF(Parametry!$B$11>0, I6 * (1 - MIN(1, K5 / MAX(1, E6+F6))) * Parametry!$B$11, 0)) -> 0 | M6: =IF(A6="","", MAX(0, E6+F6-I6+J6-L6)) -> 1497425.7
A7: =IF(Parametry!$B$8+6-1<=Parametry!$B$10, 6, "") -> 6 | B7: =IF(A7="","", Parametry!$B$8+A7-1) -> 58 | C7: =IF(A7="","", IF(B7>=Parametry!$B$9, "Dekumulacja", "Akumulacja")) -> Akumulacja | D7: =IF(A7="","", D6*(1+Parametry!$B$6)) -> 1.1592741 | E7: =IF(A7="","", M6) -> 1497425.7 | F7: =IF(A7="","", IF(C7="Akumulacja", Parametry!$B$5*12*D7, 0)) -> 41733.867 | G7: =IF(A7="","", IF(C7="Dekumulacja", Parametry!$B$4*12*D7, 0)) -> 0 | H7: =IF(A7="","", IF(C7="Dekumulacja", Parametry!$B$3*12*D7, 0)) -> 0 | I7: =IF(A7="","", MAX(0, H7-G7)) -> 0 | J7: =IF(A7="","", MAX(0, E7+F7-I7)*Parametry!$B$7) -> 76957.979 | K7: =IF(A7="","", MAX(0, K6 + F7 - I7 * MIN(1, K6 / MAX(1, E7+F7)))) -> 1232862.8 | L7: =IF(A7="","", IF(Parametry!$B$11>0, I7 * (1 - MIN(1, K6 / MAX(1, E7+F7))) * Parametry!$B$11, 0)) -> 0 | M7: =IF(A7="","", MAX(0, E7+F7-I7+J7-L7)) -> 1616117.6
A8: =IF(Parametry!$B$8+7-1<=Parametry!$B$10, 7, "") -> 7 | B8: =IF(A8="","", Parametry!$B$8+A8-1) -> 59 | C8: =IF(A8="","", IF(B8>=Parametry!$B$9, "Dekumulacja", "Akumulacja")) -> Akumulacja | D8: =IF(A8="","", D7*(1+Parametry!$B$6)) -> 1.1940523 | E8: =IF(A8="","", M7) -> 1616117.6 | F8: =IF(A8="","", IF(C8="Akumulacja", Parametry!$B$5*12*D8, 0)) -> 42985.883 | G8: =IF(A8="","", IF(C8="Dekumulacja", Parametry!$B$4*12*D8, 0)) -> 0 | H8: =IF(A8="","", IF(C8="Dekumulacja", Parametry!$B$3*12*D8, 0)) -> 0 | I8: =IF(A8="","", MAX(0, H8-G8)) -> 0 | J8: =IF(A8="","", MAX(0, E8+F8-I8)*Parametry!$B$7) -> 82955.172 | K8: =IF(A8="","", MAX(0, K7 + F8 - I8 * MIN(1, K7 / MAX(1, E8+F8)))) -> 1275848.6 | L8: =IF(A8="","", IF(Parametry!$B$11>0, I8 * (1 - MIN(1, K7 / MAX(1, E8+F8))) * Parametry!$B$11, 0)) -> 0 | M8: =IF(A8="","", MAX(0, E8+F8-I8+J8-L8)) -> 1742058.6
A9: =IF(Parametry!$B$8+8-1<=Parametry!$B$10, 8, "") -> 8 | B9: =IF(A9="","", Parametry!$B$8+A9-1) -> 60 | C9: =IF(A9="","", IF(B9>=Parametry!$B$9, "Dekumulacja", "Akumulacja")) -> Dekumulacja | D9: =IF(A9="","", D8*(1+Parametry!$B$6)) -> 1.2298739 | E9: =IF(A9="","", M8) -> 1742058.6 | F9: =IF(A9="","", IF(C9="Akumulacja", Parametry!$B$5*12*D9, 0)) -> 0 | G9: =IF(A9="","", IF(C9="Dekumulacja", Parametry!$B$4*12*D9, 0)) -> 29516.973 | H9: =IF(A9="","", IF(C9="Dekumulacja", Parametry!$B$3*12*D9, 0)) -> 73792.432 | I9: =IF(A9="","", MAX(0, H9-G9)) -> 44275.459 | J9: =IF(A9="","", MAX(0, E9+F9-I9)*Parametry!$B$7) -> 84889.158 | K9: =IF(A9="","", MAX(0, K8 + F9 - I9 * MIN(1, K8 / MAX(1, E9+F9)))) -> 1243422.2 | L9: =IF(A9="","", IF(Parametry!$B$11>0, I9 * (1 - MIN(1, K8 / MAX(1, E9+F9))) * Parametry!$B$11, 0)) -> 2251.3109 | M9: =IF(A9="","", MAX(0, E9+F9-I9+J9-L9)) -> 1780421
A10: =IF(Parametry!$B$8+9-1<=Parametry!$B$10, 9, "") -> 9 | B10: =IF(A10="","", Parametry!$B$8+A10-1) -> 61 | C10: =IF(A10="","", IF(B10>=Parametry!$B$9, "Dekumulacja", "Akumulacja")) -> Dekumulacja | D10: =IF(A10="","", D9*(1+Parametry!$B$6)) -> 1.2667701 | E10: =IF(A10="","", M9) -> 1780421 | F10: =IF(A10="","", IF(C10="Akumulacja", Parametry!$B$5*12*D10, 0)) -> 0 | G10: =IF(A10="","", IF(C10="Dekumulacja", Parametry!$B$4*12*D10, 0)) -> 30402.482 | H10: =IF(A10="","", IF(C10="Dekumulacja", Parametry!$B$3*12*D10, 0)) -> 76006.205 | I10: =IF(A10="","", MAX(0, H10-G10)) -> 45603.723 | J10: =IF(A10="","", MAX(0, E10+F10-I10)*Parametry!$B$7) -> 86740.864 | K10: =IF(A10="","", MAX(0, K9 + F10 - I10 * MIN(1, K9 / MAX(1, E10+F10)))) -> 1211573.2 | L10: =IF(A10="","", IF(Parametry!$B$11>0, I10 * (1 - MIN(1, K9 / MAX(1, E10+F10))) * Parametry!$B$11, 0)) -> 2613.3918 | M10: =IF(A10="","", MAX(0, E10+F10-I10+J10-L10)) -> 1818944.8
A11: =IF(Parametry!$B$8+10-1<=Parametry!$B$10, 10, "") -> 10 | B11: =IF(A11="","", Parametry!$B$8+A11-1) -> 62 | C11: =IF(A11="","", IF(B11>=Parametry!$B$9, "Dekumulacja", "Akumulacja")) -> Dekumulacja | D11: =IF(A11="","", D10*(1+Parametry!$B$6)) -> 1.3047732 | E11: =IF(A11="","", M10) -> 1818944.8 | F11: =IF(A11="","", IF(C11="Akumulacja", Parametry!$B$5*12*D11, 0)) -> 0 | G11: =IF(A11="","", IF(C11="Dekumulacja", Parametry!$B$4*12*D11, 0)) -> 31314.556 | H11: =IF(A11="","", IF(C11="Dekumulacja", Parametry!$B$3*12*D11, 0)) -> 78286.391 | I11: =IF(A11="","", MAX(0, H11-G11)) -> 46971.835 | J11: =IF(A11="","", MAX(0, E11+F11-I11)*Parametry!$B$7) -> 88598.646 | K11: =IF(A11="","", MAX(0, K10 + F11 - I11 * MIN(1, K10 / MAX(1, E11+F11)))) -> 1180285.9 | L11: =IF(A11="","", IF(Parametry!$B$11>0, I11 * (1 - MIN(1, K10 / MAX(1, E11+F11))) * Parametry!$B$11, 0)) -> 2980.0675 | M11: =IF(A11="","", MAX(0, E11+F11-I11+J11-L11)) -> 1857591.5
A12: =IF(Parametry!$B$8+11-1<=Parametry!$B$10, 11, "") -> 11 | B12: =IF(A12="","", Parametry!$B$8+A12-1) -> 63 | C12: =IF(A12="","", IF(B12>=Parametry!$B$9, "Dekumulacja", "Akumulacja")) -> Dekumulacja | D12: =IF(A12="","", D11*(1+Parametry!$B$6)) -> 1.3439164 | E12: =IF(A12="","", M11) -> 1857591.5 | F12: =IF(A12="","", IF(C12="Akumulacja", Parametry!$B$5*12*D12, 0)) -> 0 | G12: =IF(A12="","", IF(C12="Dekumulacja", Parametry!$B$4*12*D12, 0)) -> 32253.993 | H12: =IF(A12="","", IF(C12="Dekumulacja", Parametry!$B$3*12*D12, 0)) -> 80634.983 | I12: =IF(A12="","", MAX(0, H12-G12)) -> 48380.99 | J12: =IF(A12="","", MAX(0, E12+F12-I12)*Parametry!$B$7) -> 90460.525 | K12: =IF(A12="","", MAX(0, K11 + F12 - I12 * MIN(1, K11 / MAX(1, E12+F12)))) -> 1149545.3 | L12: =IF(A12="","", IF(Parametry!$B$11>0, I12 * (1 - MIN(1, K11 / MAX(1, E12+F12))) * Parametry!$B$11, 0)) -> 3351.682 | M12: =IF(A12="","", MAX(0, E12+F12-I12+J12-L12)) -> 1896319.4
A13: =IF(Parametry!$B$8+12-1<=Parametry!$B$10, 12, "") -> 12 | B13: =IF(A13="","", Parametry!$B$8+A13-1) -> 64 | C13: =IF(A13="","", IF(B13>=Parametry!$B$9, "Dekumulacja", "Akumulacja")) -> Dekumulacja | D13: =IF(A13="","", D12*(1+Parametry!$B$6)) -> 1.3842339 | E13: =IF(A13="","", M12) -> 1896319.4 | F13: =IF(A13="","", IF(C13="Akumulacja", Parametry!$B$5*12*D13, 0)) -> 0 | G13: =IF(A13="","", IF(C13="Dekumulacja", Parametry!$B$4*12*D13, 0)) -> 33221.613 | H13: =IF(A13="","", IF(C13="Dekumulacja", Parametry!$B$3*12*D13, 0)) -> 83054.032 | I13: =IF(A13="","", MAX(0, H13-G13)) -> 49832.419 | J13: =IF(A13="","", MAX(0, E13+F13-I13)*Parametry!$B$7) -> 92324.347 | K13: =IF(A13="","", MAX(0, K12 + F13 - I13 * MIN(1, K12 / MAX(1, E13+F13)))) -> 1119337 | L13: =IF(A13="","", IF(Parametry!$B$11>0, I13 * (1 - MIN(1, K12 / MAX(1, E13+F13))) * Parametry!$B$11, 0)) -> 3728.5786 | M13: =IF(A13="","", MAX(0, E13+F13-I13+J13-L13)) -> 1935082.7
A14: =IF(Parametry!$B$8+13-1<=Parametry!$B$10, 13, "") -> 13 | B14: =IF(A14="","", Parametry!$B$8+A14-1) -> 65 | C14: =IF(A14="","", IF(B14>=Parametry!$B$9, "Dekumulacja", "Akumulacja")) -> Dekumulacja | D14: =IF(A14="","", D13*(1+Parametry!$B$6)) -> 1.4257609 | E14: =IF(A14="","", M13) -> 1935082.7 | F14: =IF(A14="","", IF(C14="Akumulacja", Parametry!$B$5*12*D14, 0)) -> 0 | G14: =IF(A14="","", IF(C14="Dekumulacja", Parametry!$B$4*12*D14, 0)) -> 34218.261 | H14: =IF(A14="","", IF(C14="Dekumulacja", Parametry!$B$3*12*D14, 0)) -> 85545.653 | I14: =IF(A14="","", MAX(0, H14-G14)) -> 51327.392 | J14: =IF(A14="","", MAX(0, E14+F14-I14)*Parametry!$B$7) -> 94187.765 | K14: =IF(A14="","", MAX(0, K13 + F14 - I14 * MIN(1, K13 / MAX(1, E14+F14)))) -> 1089647 | L14: =IF(A14="","", IF(Parametry!$B$11>0, I14 * (1 - MIN(1, K13 / MAX(1, E14+F14))) * Parametry!$B$11, 0)) -> 4111.1002 | M14: =IF(A14="","", MAX(0, E14+F14-I14+J14-L14)) -> 1973832
A15: =IF(Parametry!$B$8+14-1<=Parametry!$B$10, 14, "") | B15: =IF(A15="","", Parametry!$B$8+A15-1) | C15: =IF(A15="","", IF(B15>=Parametry!$B$9, "Dekumulacja", "Akumulacja")) | D15: =IF(A15="","", D14*(1+Parametry!$B$6)) | E15: =IF(A15="","", M14) | F15: =IF(A15="","", IF(C15="Akumulacja", Parametry!$B$5*12*D15, 0)) | G15: =IF(A15="","", IF(C15="Dekumulacja", Parametry!$B$4*12*D15, 0)) | H15: =IF(A15="","", IF(C15="Dekumulacja", Parametry!$B$3*12*D15, 0)) | I15: =IF(A15="","", MAX(0, H15-G15)) | J15: =IF(A15="","", MAX(0, E15+F15-I15)*Parametry!$B$7) | K15: =IF(A15="","", MAX(0, K14 + F15 - I15 * MIN(1, K14 / MAX(1, E15+F15)))) | L15: =IF(A15="","", IF(Parametry!$B$11>0, I15 * (1 - MIN(1, K14 / MAX(1, E15+F15))) * Parametry!$B$11, 0)) | M15: =IF(A15="","", MAX(0, E15+F15-I15+J15-L15))
A16: =IF(Parametry!$B$8+15-1<=Parametry!$B$10, 15, "") | B16: =IF(A16="","", Parametry!$B$8+A16-1) | C16: =IF(A16="","", IF(B16>=Parametry!$B$9, "Dekumulacja", "Akumulacja")) | D16: =IF(A16="","", D15*(1+Parametry!$B$6)) | E16: =IF(A16="","", M15) | F16: =IF(A16="","", IF(C16="Akumulacja", Parametry!$B$5*12*D16, 0)) | G16: =IF(A16="","", IF(C16="Dekumulacja", Parametry!$B$4*12*D16, 0)) | H16: =IF(A16="","", IF(C16="Dekumulacja", Parametry!$B$3*12*D16, 0)) | I16: =IF(A16="","", MAX(0, H16-G16)) | J16: =IF(A16="","", MAX(0, E16+F16-I16)*Parametry!$B$7) | K16: =IF(A16="","", MAX(0, K15 + F16 - I16 * MIN(1, K15 / MAX(1, E16+F16)))) | L16: =IF(A16="","", IF(Parametry!$B$11>0, I16 * (1 - MIN(1, K15 / MAX(1, E16+F16))) * Parametry!$B$11, 0)) | M16: =IF(A16="","", MAX(0, E16+F16-I16+J16-L16))
A17: =IF(Parametry!$B$8+16-1<=Parametry!$B$10, 16, "") | B17: =IF(A17="","", Parametry!$B$8+A17-1) | C17: =IF(A17="","", IF(B17>=Parametry!$B$9, "Dekumulacja", "Akumulacja")) | D17: =IF(A17="","", D16*(1+Parametry!$B$6)) | E17: =IF(A17="","", M16) | F17: =IF(A17="","", IF(C17="Akumulacja", Parametry!$B$5*12*D17, 0)) | G17: =IF(A17="","", IF(C17="Dekumulacja", Parametry!$B$4*12*D17, 0)) | H17: =IF(A17="","", IF(C17="Dekumulacja", Parametry!$B$3*12*D17, 0)) | I17: =IF(A17="","", MAX(0, H17-G17)) | J17: =IF(A17="","", MAX(0, E17+F17-I17)*Parametry!$B$7) | K17: =IF(A17="","", MAX(0, K16 + F17 - I17 * MIN(1, K16 / MAX(1, E17+F17)))) | L17: =IF(A17="","", IF(Parametry!$B$11>0, I17 * (1 - MIN(1, K16 / MAX(1, E17+F17))) * Parametry!$B$11, 0)) | M17: =IF(A17="","", MAX(0, E17+F17-I17+J17-L17))
A18: =IF(Parametry!$B$8+17-1<=Parametry!$B$10, 17, "") | B18: =IF(A18="","", Parametry!$B$8+A18-1) | C18: =IF(A18="","", IF(B18>=Parametry!$B$9, "Dekumulacja", "Akumulacja")) | D18: =IF(A18="","", D17*(1+Parametry!$B$6)) | E18: =IF(A18="","", M17) | F18: =IF(A18="","", IF(C18="Akumulacja", Parametry!$B$5*12*D18, 0)) | G18: =IF(A18="","", IF(C18="Dekumulacja", Parametry!$B$4*12*D18, 0)) | H18: =IF(A18="","", IF(C18="Dekumulacja", Parametry!$B$3*12*D18, 0)) | I18: =IF(A18="","", MAX(0, H18-G18)) | J18: =IF(A18="","", MAX(0, E18+F18-I18)*Parametry!$B$7) | K18: =IF(A18="","", MAX(0, K17 + F18 - I18 * MIN(1, K17 / MAX(1, E18+F18)))) | L18: =IF(A18="","", IF(Parametry!$B$11>0, I18 * (1 - MIN(1, K17 / MAX(1, E18+F18))) * Parametry!$B$11, 0)) | M18: =IF(A18="","", MAX(0, E18+F18-I18+J18-L18))
A19: =IF(Parametry!$B$8+18-1<=Parametry!$B$10, 18, "") | B19: =IF(A19="","", Parametry!$B$8+A19-1) | C19: =IF(A19="","", IF(B19>=Parametry!$B$9, "Dekumulacja", "Akumulacja")) | D19: =IF(A19="","", D18*(1+Parametry!$B$6)) | E19: =IF(A19="","", M18) | F19: =IF(A19="","", IF(C19="Akumulacja", Parametry!$B$5*12*D19, 0)) | G19: =IF(A19="","", IF(C19="Dekumulacja", Parametry!$B$4*12*D19, 0)) | H19: =IF(A19="","", IF(C19="Dekumulacja", Parametry!$B$3*12*D19, 0)) | I19: =IF(A19="","", MAX(0, H19-G19)) | J19: =IF(A19="","", MAX(0, E19+F19-I19)*Parametry!$B$7) | K19: =IF(A19="","", MAX(0, K18 + F19 - I19 * MIN(1, K18 / MAX(1, E19+F19)))) | L19: =IF(A19="","", IF(Parametry!$B$11>0, I19 * (1 - MIN(1, K18 / MAX(1, E19+F19))) * Parametry!$B$11, 0)) | M19: =IF(A19="","", MAX(0, E19+F19-I19+J19-L19))
A20: =IF(Parametry!$B$8+19-1<=Parametry!$B$10, 19, "") | B20: =IF(A20="","", Parametry!$B$8+A20-1) | C20: =IF(A20="","", IF(B20>=Parametry!$B$9, "Dekumulacja", "Akumulacja")) | D20: =IF(A20="","", D19*(1+Parametry!$B$6)) | E20: =IF(A20="","", M19) | F20: =IF(A20="","", IF(C20="Akumulacja", Parametry!$B$5*12*D20, 0)) | G20: =IF(A20="","", IF(C20="Dekumulacja", Parametry!$B$4*12*D20, 0)) | H20: =IF(A20="","", IF(C20="Dekumulacja", Parametry!$B$3*12*D20, 0)) | I20: =IF(A20="","", MAX(0, H20-G20)) | J20: =IF(A20="","", MAX(0, E20+F20-I20)*Parametry!$B$7) | K20: =IF(A20="","", MAX(0, K19 + F20 - I20 * MIN(1, K19 / MAX(1, E20+F20)))) | L20: =IF(A20="","", IF(Parametry!$B$11>0, I20 * (1 - MIN(1, K19 / MAX(1, E20+F20))) * Parametry!$B$11, 0)) | M20: =IF(A20="","", MAX(0, E20+F20-I20+J20-L20))
A21: =IF(Parametry!$B$8+20-1<=Parametry!$B$10, 20, "") | B21: =IF(A21="","", Parametry!$B$8+A21-1) | C21: =IF(A21="","", IF(B21>=Parametry!$B$9, "Dekumulacja", "Akumulacja")) | D21: =IF(A21="","", D20*(1+Parametry!$B$6)) | E21: =IF(A21="","", M20) | F21: =IF(A21="","", IF(C21="Akumulacja", Parametry!$B$5*12*D21, 0)) | G21: =IF(A21="","", IF(C21="Dekumulacja", Parametry!$B$4*12*D21, 0)) | H21: =IF(A21="","", IF(C21="Dekumulacja", Parametry!$B$3*12*D21, 0)) | I21: =IF(A21="","", MAX(0, H21-G21)) | J21: =IF(A21="","", MAX(0, E21+F21-I21)*Parametry!$B$7) | K21: =IF(A21="","", MAX(0, K20 + F21 - I21 * MIN(1, K20 / MAX(1, E21+F21)))) | L21: =IF(A21="","", IF(Parametry!$B$11>0, I21 * (1 - MIN(1, K20 / MAX(1, E21+F21))) * Parametry!$B$11, 0)) | M21: =IF(A21="","", MAX(0, E21+F21-I21+J21-L21))
A22: =IF(Parametry!$B$8+21-1<=Parametry!$B$10, 21, "") | B22: =IF(A22="","", Parametry!$B$8+A22-1) | C22: =IF(A22="","", IF(B22>=Parametry!$B$9, "Dekumulacja", "Akumulacja")) | D22: =IF(A22="","", D21*(1+Parametry!$B$6)) | E22: =IF(A22="","", M21) | F22: =IF(A22="","", IF(C22="Akumulacja", Parametry!$B$5*12*D22, 0)) | G22: =IF(A22="","", IF(C22="Dekumulacja", Parametry!$B$4*12*D22, 0)) | H22: =IF(A22="","", IF(C22="Dekumulacja", Parametry!$B$3*12*D22, 0)) | I22: =IF(A22="","", MAX(0, H22-G22)) | J22: =IF(A22="","", MAX(0, E22+F22-I22)*Parametry!$B$7) | K22: =IF(A22="","", MAX(0, K21 + F22 - I22 * MIN(1, K21 / MAX(1, E22+F22)))) | L22: =IF(A22="","", IF(Parametry!$B$11>0, I22 * (1 - MIN(1, K21 / MAX(1, E22+F22))) * Parametry!$B$11, 0)) | M22: =IF(A22="","", MAX(0, E22+F22-I22+J22-L22))
A23: =IF(Parametry!$B$8+22-1<=Parametry!$B$10, 22, "") | B23: =IF(A23="","", Parametry!$B$8+A23-1) | C23: =IF(A23="","", IF(B23>=Parametry!$B$9, "Dekumulacja", "Akumulacja")) | D23: =IF(A23="","", D22*(1+Parametry!$B$6)) | E23: =IF(A23="","", M22) | F23: =IF(A23="","", IF(C23="Akumulacja", Parametry!$B$5*12*D23, 0)) | G23: =IF(A23="","", IF(C23="Dekumulacja", Parametry!$B$4*12*D23, 0)) | H23: =IF(A23="","", IF(C23="Dekumulacja", Parametry!$B$3*12*D23, 0)) | I23: =IF(A23="","", MAX(0, H23-G23)) | J23: =IF(A23="","", MAX(0, E23+F23-I23)*Parametry!$B$7) | K23: =IF(A23="","", MAX(0, K22 + F23 - I23 * MIN(1, K22 / MAX(1, E23+F23)))) | L23: =IF(A23="","", IF(Parametry!$B$11>0, I23 * (1 - MIN(1, K22 / MAX(1, E23+F23))) * Parametry!$B$11, 0)) | M23: =IF(A23="","", MAX(0, E23+F23-I23+J23-L23))
A24: =IF(Parametry!$B$8+23-1<=Parametry!$B$10, 23, "") | B24: =IF(A24="","", Parametry!$B$8+A24-1) | C24: =IF(A24="","", IF(B24>=Parametry!$B$9, "Dekumulacja", "Akumulacja")) | D24: =IF(A24="","", D23*(1+Parametry!$B$6)) | E24: =IF(A24="","", M23) | F24: =IF(A24="","", IF(C24="Akumulacja", Parametry!$B$5*12*D24, 0)) | G24: =IF(A24="","", IF(C24="Dekumulacja", Parametry!$B$4*12*D24, 0)) | H24: =IF(A24="","", IF(C24="Dekumulacja", Parametry!$B$3*12*D24, 0)) | I24: =IF(A24="","", MAX(0, H24-G24)) | J24: =IF(A24="","", MAX(0, E24+F24-I24)*Parametry!$B$7) | K24: =IF(A24="","", MAX(0, K23 + F24 - I24 * MIN(1, K23 / MAX(1, E24+F24)))) | L24: =IF(A24="","", IF(Parametry!$B$11>0, I24 * (1 - MIN(1, K23 / MAX(1, E24+F24))) * Parametry!$B$11, 0)) | M24: =IF(A24="","", MAX(0, E24+F24-I24+J24-L24))
A25: =IF(Parametry!$B$8+24-1<=Parametry!$B$10, 24, "") | B25: =IF(A25="","", Parametry!$B$8+A25-1) | C25: =IF(A25="","", IF(B25>=Parametry!$B$9, "Dekumulacja", "Akumulacja")) | D25: =IF(A25="","", D24*(1+Parametry!$B$6)) | E25: =IF(A25="","", M24) | F25: =IF(A25="","", IF(C25="Akumulacja", Parametry!$B$5*12*D25, 0)) | G25: =IF(A25="","", IF(C25="Dekumulacja", Parametry!$B$4*12*D25, 0)) | H25: =IF(A25="","", IF(C25="Dekumulacja", Parametry!$B$3*12*D25, 0)) | I25: =IF(A25="","", MAX(0, H25-G25)) | J25: =IF(A25="","", MAX(0, E25+F25-I25)*Parametry!$B$7) | K25: =IF(A25="","", MAX(0, K24 + F25 - I25 * MIN(1, K24 / MAX(1, E25+F25)))) | L25: =IF(A25="","", IF(Parametry!$B$11>0, I25 * (1 - MIN(1, K24 / MAX(1, E25+F25))) * Parametry!$B$11, 0)) | M25: =IF(A25="","", MAX(0, E25+F25-I25+J25-L25))
A26: =IF(Parametry!$B$8+25-1<=Parametry!$B$10, 25, "") | B26: =IF(A26="","", Parametry!$B$8+A26-1) | C26: =IF(A26="","", IF(B26>=Parametry!$B$9, "Dekumulacja", "Akumulacja")) | D26: =IF(A26="","", D25*(1+Parametry!$B$6)) | E26: =IF(A26="","", M25) | F26: =IF(A26="","", IF(C26="Akumulacja", Parametry!$B$5*12*D26, 0)) | G26: =IF(A26="","", IF(C26="Dekumulacja", Parametry!$B$4*12*D26, 0)) | H26: =IF(A26="","", IF(C26="Dekumulacja", Parametry!$B$3*12*D26, 0)) | I26: =IF(A26="","", MAX(0, H26-G26)) | J26: =IF(A26="","", MAX(0, E26+F26-I26)*Parametry!$B$7) | K26: =IF(A26="","", MAX(0, K25 + F26 - I26 * MIN(1, K25 / MAX(1, E26+F26)))) | L26: =IF(A26="","", IF(Parametry!$B$11>0, I26 * (1 - MIN(1, K25 / MAX(1, E26+F26))) * Parametry!$B$11, 0)) | M26: =IF(A26="","", MAX(0, E26+F26-I26+J26-L26))
A27: =IF(Parametry!$B$8+26-1<=Parametry!$B$10, 26, "") | B27: =IF(A27="","", Parametry!$B$8+A27-1) | C27: =IF(A27="","", IF(B27>=Parametry!$B$9, "Dekumulacja", "Akumulacja")) | D27: =IF(A27="","", D26*(1+Parametry!$B$6)) | E27: =IF(A27="","", M26) | F27: =IF(A27="","", IF(C27="Akumulacja", Parametry!$B$5*12*D27, 0)) | G27: =IF(A27="","", IF(C27="Dekumulacja", Parametry!$B$4*12*D27, 0)) | H27: =IF(A27="","", IF(C27="Dekumulacja", Parametry!$B$3*12*D27, 0)) | I27: =IF(A27="","", MAX(0, H27-G27)) | J27: =IF(A27="","", MAX(0, E27+F27-I27)*Parametry!$B$7) | K27: =IF(A27="","", MAX(0, K26 + F27 - I27 * MIN(1, K26 / MAX(1, E27+F27)))) | L27: =IF(A27="","", IF(Parametry!$B$11>0, I27 * (1 - MIN(1, K26 / MAX(1, E27+F27))) * Parametry!$B$11, 0)) | M27: =IF(A27="","", MAX(0, E27+F27-I27+J27-L27))
A28: =IF(Parametry!$B$8+27-1<=Parametry!$B$10, 27, "") | B28: =IF(A28="","", Parametry!$B$8+A28-1) | C28: =IF(A28="","", IF(B28>=Parametry!$B$9, "Dekumulacja", "Akumulacja")) | D28: =IF(A28="","", D27*(1+Parametry!$B$6)) | E28: =IF(A28="","", M27) | F28: =IF(A28="","", IF(C28="Akumulacja", Parametry!$B$5*12*D28, 0)) | G28: =IF(A28="","", IF(C28="Dekumulacja", Parametry!$B$4*12*D28, 0)) | H28: =IF(A28="","", IF(C28="Dekumulacja", Parametry!$B$3*12*D28, 0)) | I28: =IF(A28="","", MAX(0, H28-G28)) | J28: =IF(A28="","", MAX(0, E28+F28-I28)*Parametry!$B$7) | K28: =IF(A28="","", MAX(0, K27 + F28 - I28 * MIN(1, K27 / MAX(1, E28+F28)))) | L28: =IF(A28="","", IF(Parametry!$B$11>0, I28 * (1 - MIN(1, K27 / MAX(1, E28+F28))) * Parametry!$B$11, 0)) | M28: =IF(A28="","", MAX(0, E28+F28-I28+J28-L28))
A29: =IF(Parametry!$B$8+28-1<=Parametry!$B$10, 28, "") | B29: =IF(A29="","", Parametry!$B$8+A29-1) | C29: =IF(A29="","", IF(B29>=Parametry!$B$9, "Dekumulacja", "Akumulacja")) | D29: =IF(A29="","", D28*(1+Parametry!$B$6)) | E29: =IF(A29="","", M28) | F29: =IF(A29="","", IF(C29="Akumulacja", Parametry!$B$5*12*D29, 0)) | G29: =IF(A29="","", IF(C29="Dekumulacja", Parametry!$B$4*12*D29, 0)) | H29: =IF(A29="","", IF(C29="Dekumulacja", Parametry!$B$3*12*D29, 0)) | I29: =IF(A29="","", MAX(0, H29-G29)) | J29: =IF(A29="","", MAX(0, E29+F29-I29)*Parametry!$B$7) | K29: =IF(A29="","", MAX(0, K28 + F29 - I29 * MIN(1, K28 / MAX(1, E29+F29)))) | L29: =IF(A29="","", IF(Parametry!$B$11>0, I29 * (1 - MIN(1, K28 / MAX(1, E29+F29))) * Parametry!$B$11, 0)) | M29: =IF(A29="","", MAX(0, E29+F29-I29+J29-L29))
A30: =IF(Parametry!$B$8+29-1<=Parametry!$B$10, 29, "") | B30: =IF(A30="","", Parametry!$B$8+A30-1) | C30: =IF(A30="","", IF(B30>=Parametry!$B$9, "Dekumulacja", "Akumulacja")) | D30: =IF(A30="","", D29*(1+Parametry!$B$6)) | E30: =IF(A30="","", M29) | F30: =IF(A30="","", IF(C30="Akumulacja", Parametry!$B$5*12*D30, 0)) | G30: =IF(A30="","", IF(C30="Dekumulacja", Parametry!$B$4*12*D30, 0)) | H30: =IF(A30="","", IF(C30="Dekumulacja", Parametry!$B$3*12*D30, 0)) | I30: =IF(A30="","", MAX(0, H30-G30)) | J30: =IF(A30="","", MAX(0, E30+F30-I30)*Parametry!$B$7) | K30: =IF(A30="","", MAX(0, K29 + F30 - I30 * MIN(1, K29 / MAX(1, E30+F30)))) | L30: =IF(A30="","", IF(Parametry!$B$11>0, I30 * (1 - MIN(1, K29 / MAX(1, E30+F30))) * Parametry!$B$11, 0)) | M30: =IF(A30="","", MAX(0, E30+F30-I30+J30-L30))
A31: =IF(Parametry!$B$8+30-1<=Parametry!$B$10, 30, "") | B31: =IF(A31="","", Parametry!$B$8+A31-1) | C31: =IF(A31="","", IF(B31>=Parametry!$B$9, "Dekumulacja", "Akumulacja")) | D31: =IF(A31="","", D30*(1+Parametry!$B$6)) | E31: =IF(A31="","", M30) | F31: =IF(A31="","", IF(C31="Akumulacja", Parametry!$B$5*12*D31, 0)) | G31: =IF(A31="","", IF(C31="Dekumulacja", Parametry!$B$4*12*D31, 0)) | H31: =IF(A31="","", IF(C31="Dekumulacja", Parametry!$B$3*12*D31, 0)) | I31: =IF(A31="","", MAX(0, H31-G31)) | J31: =IF(A31="","", MAX(0, E31+F31-I31)*Parametry!$B$7) | K31: =IF(A31="","", MAX(0, K30 + F31 - I31 * MIN(1, K30 / MAX(1, E31+F31)))) | L31: =IF(A31="","", IF(Parametry!$B$11>0, I31 * (1 - MIN(1, K30 / MAX(1, E31+F31))) * Parametry!$B$11, 0)) | M31: =IF(A31="","", MAX(0, E31+F31-I31+J31-L31))
A32: =IF(Parametry!$B$8+31-1<=Parametry!$B$10, 31, "") | B32: =IF(A32="","", Parametry!$B$8+A32-1) | C32: =IF(A32="","", IF(B32>=Parametry!$B$9, "Dekumulacja", "Akumulacja")) | D32: =IF(A32="","", D31*(1+Parametry!$B$6)) | E32: =IF(A32="","", M31) | F32: =IF(A32="","", IF(C32="Akumulacja", Parametry!$B$5*12*D32, 0)) | G32: =IF(A32="","", IF(C32="Dekumulacja", Parametry!$B$4*12*D32, 0)) | H32: =IF(A32="","", IF(C32="Dekumulacja", Parametry!$B$3*12*D32, 0)) | I32: =IF(A32="","", MAX(0, H32-G32)) | J32: =IF(A32="","", MAX(0, E32+F32-I32)*Parametry!$B$7) | K32: =IF(A32="","", MAX(0, K31 + F32 - I32 * MIN(1, K31 / MAX(1, E32+F32)))) | L32: =IF(A32="","", IF(Parametry!$B$11>0, I32 * (1 - MIN(1, K31 / MAX(1, E32+F32))) * Parametry!$B$11, 0)) | M32: =IF(A32="","", MAX(0, E32+F32-I32+J32-L32))
A33: =IF(Parametry!$B$8+32-1<=Parametry!$B$10, 32, "") | B33: =IF(A33="","", Parametry!$B$8+A33-1) | C33: =IF(A33="","", IF(B33>=Parametry!$B$9, "Dekumulacja", "Akumulacja")) | D33: =IF(A33="","", D32*(1+Parametry!$B$6)) | E33: =IF(A33="","", M32) | F33: =IF(A33="","", IF(C33="Akumulacja", Parametry!$B$5*12*D33, 0)) | G33: =IF(A33="","", IF(C33="Dekumulacja", Parametry!$B$4*12*D33, 0)) | H33: =IF(A33="","", IF(C33="Dekumulacja", Parametry!$B$3*12*D33, 0)) | I33: =IF(A33="","", MAX(0, H33-G33)) | J33: =IF(A33="","", MAX(0, E33+F33-I33)*Parametry!$B$7) | K33: =IF(A33="","", MAX(0, K32 + F33 - I33 * MIN(1, K32 / MAX(1, E33+F33)))) | L33: =IF(A33="","", IF(Parametry!$B$11>0, I33 * (1 - MIN(1, K32 / MAX(1, E33+F33))) * Parametry!$B$11, 0)) | M33: =IF(A33="","", MAX(0, E33+F33-I33+J33-L33))
A34: =IF(Parametry!$B$8+33-1<=Parametry!$B$10, 33, "") | B34: =IF(A34="","", Parametry!$B$8+A34-1) | C34: =IF(A34="","", IF(B34>=Parametry!$B$9, "Dekumulacja", "Akumulacja")) | D34: =IF(A34="","", D33*(1+Parametry!$B$6)) | E34: =IF(A34="","", M33) | F34: =IF(A34="","", IF(C34="Akumulacja", Parametry!$B$5*12*D34, 0)) | G34: =IF(A34="","", IF(C34="Dekumulacja", Parametry!$B$4*12*D34, 0)) | H34: =IF(A34="","", IF(C34="Dekumulacja", Parametry!$B$3*12*D34, 0)) | I34: =IF(A34="","", MAX(0, H34-G34)) | J34: =IF(A34="","", MAX(0, E34+F34-I34)*Parametry!$B$7) | K34: =IF(A34="","", MAX(0, K33 + F34 - I34 * MIN(1, K33 / MAX(1, E34+F34)))) | L34: =IF(A34="","", IF(Parametry!$B$11>0, I34 * (1 - MIN(1, K33 / MAX(1, E34+F34))) * Parametry!$B$11, 0)) | M34: =IF(A34="","", MAX(0, E34+F34-I34+J34-L34))
A35: =IF(Parametry!$B$8+34-1<=Parametry!$B$10, 34, "") | B35: =IF(A35="","", Parametry!$B$8+A35-1) | C35: =IF(A35="","", IF(B35>=Parametry!$B$9, "Dekumulacja", "Akumulacja")) | D35: =IF(A35="","", D34*(1+Parametry!$B$6)) | E35: =IF(A35="","", M34) | F35: =IF(A35="","", IF(C35="Akumulacja", Parametry!$B$5*12*D35, 0)) | G35: =IF(A35="","", IF(C35="Dekumulacja", Parametry!$B$4*12*D35, 0)) | H35: =IF(A35="","", IF(C35="Dekumulacja", Parametry!$B$3*12*D35, 0)) | I35: =IF(A35="","", MAX(0, H35-G35)) | J35: =IF(A35="","", MAX(0, E35+F35-I35)*Parametry!$B$7) | K35: =IF(A35="","", MAX(0, K34 + F35 - I35 * MIN(1, K34 / MAX(1, E35+F35)))) | L35: =IF(A35="","", IF(Parametry!$B$11>0, I35 * (1 - MIN(1, K34 / MAX(1, E35+F35))) * Parametry!$B$11, 0)) | M35: =IF(A35="","", MAX(0, E35+F35-I35+J35-L35))
A36: =IF(Parametry!$B$8+35-1<=Parametry!$B$10, 35, "") | B36: =IF(A36="","", Parametry!$B$8+A36-1) | C36: =IF(A36="","", IF(B36>=Parametry!$B$9, "Dekumulacja", "Akumulacja")) | D36: =IF(A36="","", D35*(1+Parametry!$B$6)) | E36: =IF(A36="","", M35) | F36: =IF(A36="","", IF(C36="Akumulacja", Parametry!$B$5*12*D36, 0)) | G36: =IF(A36="","", IF(C36="Dekumulacja", Parametry!$B$4*12*D36, 0)) | H36: =IF(A36="","", IF(C36="Dekumulacja", Parametry!$B$3*12*D36, 0)) | I36: =IF(A36="","", MAX(0, H36-G36)) | J36: =IF(A36="","", MAX(0, E36+F36-I36)*Parametry!$B$7) | K36: =IF(A36="","", MAX(0, K35 + F36 - I36 * MIN(1, K35 / MAX(1, E36+F36)))) | L36: =IF(A36="","", IF(Parametry!$B$11>0, I36 * (1 - MIN(1, K35 / MAX(1, E36+F36))) * Parametry!$B$11, 0)) | M36: =IF(A36="","", MAX(0, E36+F36-I36+J36-L36))
A37: =IF(Parametry!$B$8+36-1<=Parametry!$B$10, 36, "") | B37: =IF(A37="","", Parametry!$B$8+A37-1) | C37: =IF(A37="","", IF(B37>=Parametry!$B$9, "Dekumulacja", "Akumulacja")) | D37: =IF(A37="","", D36*(1+Parametry!$B$6)) | E37: =IF(A37="","", M36) | F37: =IF(A37="","", IF(C37="Akumulacja", Parametry!$B$5*12*D37, 0)) | G37: =IF(A37="","", IF(C37="Dekumulacja", Parametry!$B$4*12*D37, 0)) | H37: =IF(A37="","", IF(C37="Dekumulacja", Parametry!$B$3*12*D37, 0)) | I37: =IF(A37="","", MAX(0, H37-G37)) | J37: =IF(A37="","", MAX(0, E37+F37-I37)*Parametry!$B$7) | K37: =IF(A37="","", MAX(0, K36 + F37 - I37 * MIN(1, K36 / MAX(1, E37+F37)))) | L37: =IF(A37="","", IF(Parametry!$B$11>0, I37 * (1 - MIN(1, K36 / MAX(1, E37+F37))) * Parametry!$B$11, 0)) | M37: =IF(A37="","", MAX(0, E37+F37-I37+J37-L37))
A38: =IF(Parametry!$B$8+37-1<=Parametry!$B$10, 37, "") | B38: =IF(A38="","", Parametry!$B$8+A38-1) | C38: =IF(A38="","", IF(B38>=Parametry!$B$9, "Dekumulacja", "Akumulacja")) | D38: =IF(A38="","", D37*(1+Parametry!$B$6)) | E38: =IF(A38="","", M37) | F38: =IF(A38="","", IF(C38="Akumulacja", Parametry!$B$5*12*D38, 0)) | G38: =IF(A38="","", IF(C38="Dekumulacja", Parametry!$B$4*12*D38, 0)) | H38: =IF(A38="","", IF(C38="Dekumulacja", Parametry!$B$3*12*D38, 0)) | I38: =IF(A38="","", MAX(0, H38-G38)) | J38: =IF(A38="","", MAX(0, E38+F38-I38)*Parametry!$B$7) | K38: =IF(A38="","", MAX(0, K37 + F38 - I38 * MIN(1, K37 / MAX(1, E38+F38)))) | L38: =IF(A38="","", IF(Parametry!$B$11>0, I38 * (1 - MIN(1, K37 / MAX(1, E38+F38))) * Parametry!$B$11, 0)) | M38: =IF(A38="","", MAX(0, E38+F38-I38+J38-L38))
A39: =IF(Parametry!$B$8+38-1<=Parametry!$B$10, 38, "") | B39: =IF(A39="","", Parametry!$B$8+A39-1) | C39: =IF(A39="","", IF(B39>=Parametry!$B$9, "Dekumulacja", "Akumulacja")) | D39: =IF(A39="","", D38*(1+Parametry!$B$6)) | E39: =IF(A39="","", M38) | F39: =IF(A39="","", IF(C39="Akumulacja", Parametry!$B$5*12*D39, 0)) | G39: =IF(A39="","", IF(C39="Dekumulacja", Parametry!$B$4*12*D39, 0)) | H39: =IF(A39="","", IF(C39="Dekumulacja", Parametry!$B$3*12*D39, 0)) | I39: =IF(A39="","", MAX(0, H39-G39)) | J39: =IF(A39="","", MAX(0, E39+F39-I39)*Parametry!$B$7) | K39: =IF(A39="","", MAX(0, K38 + F39 - I39 * MIN(1, K38 / MAX(1, E39+F39)))) | L39: =IF(A39="","", IF(Parametry!$B$11>0, I39 * (1 - MIN(1, K38 / MAX(1, E39+F39))) * Parametry!$B$11, 0)) | M39: =IF(A39="","", MAX(0, E39+F39-I39+J39-L39))
A40: =IF(Parametry!$B$8+39-1<=Parametry!$B$10, 39, "") | B40: =IF(A40="","", Parametry!$B$8+A40-1) | C40: =IF(A40="","", IF(B40>=Parametry!$B$9, "Dekumulacja", "Akumulacja")) | D40: =IF(A40="","", D39*(1+Parametry!$B$6)) | E40: =IF(A40="","", M39) | F40: =IF(A40="","", IF(C40="Akumulacja", Parametry!$B$5*12*D40, 0)) | G40: =IF(A40="","", IF(C40="Dekumulacja", Parametry!$B$4*12*D40, 0)) | H40: =IF(A40="","", IF(C40="Dekumulacja", Parametry!$B$3*12*D40, 0)) | I40: =IF(A40="","", MAX(0, H40-G40)) | J40: =IF(A40="","", MAX(0, E40+F40-I40)*Parametry!$B$7) | K40: =IF(A40="","", MAX(0, K39 + F40 - I40 * MIN(1, K39 / MAX(1, E40+F40)))) | L40: =IF(A40="","", IF(Parametry!$B$11>0, I40 * (1 - MIN(1, K39 / MAX(1, E40+F40))) * Parametry!$B$11, 0)) | M40: =IF(A40="","", MAX(0, E40+F40-I40+J40-L40))
...

Sheet Wykres
